<!DOCTYPE html>
<html lang="en">
<head>
  <meta charset="UTF-8">
  <title>5.promise异常传透</title>
</head>
<body>
<script>
  /*
  6.promise异常传/穿透?
    1. 当使用promise的then链式调用时, 可以在最后指定失败的回调,
    2. 前面任何操作出了异常, 都会传到最后失败的回调中处理
  */

  new Promise((resolve, reject) => {
    // resolve(1)
    reject(1)
  }).then(
    value => {
      console.log('onResolved1()', value)
      return 2
    },
    // reason => {throw reason} //如果没有reject回调,就类似这样往下传递
  ).then(
    value => {
      console.log('onResolved2()', value)
      return 3
    },
    //reason => {throw reason} //如果没有reject回调,就类似这样往下传递
  ).then(
    value => {
      console.log('onResolved3()', value)
    },
    //reason => Promise.reject(reason) //如果没有reject回调,就类似这样往下传递
  ).catch(reason => {
    console.log('onReejected1()', reason)
    // throw reason
    // return Promise.reject(reason)
  }).then(
    value => {
      console.log('onResolved3()', value)
    },
    reason => {
      console.log('onReejected2()', reason)
    }
  )

</script>
</body>
</html>
